Workbook

Sheet 个人填写表单
A1: 2024-2025学年管理学院本科生素质能力评价量化评分表
B2: 学号 | C2: 202218271084 | D2: 姓名 | E2: 文雪 | F2: 年级 | G2: 23级 | H2: 班级 | I2: 供应链管理
A3: 模块 | B3: 类别 | C3: 活动名称 | D3: 参与类别 | E3: 获奖级别 | F3: 获奖等级 | G3: 加分 | H3: 小计 | I3: 总计 | J3: 备注
A4: 身 心 素 养 | B4: 基础性 评价 | C4: 《国家学生体质健康标准》测试达标 | D4: 个人项目 | E4: 校级 | F4: 参与 | G4: =LOOKUP(0,0/((D4=得分表!C:C)*(E4=得分表!D:D)*(F4=得分表!E:E)),得分表!F:F) -> 6 | H4: =IF(SUM(G4:G6)<9,SUM(G4:G6),9) -> 9 | I4: =H4+H7 -> 9 | J4: 基础性评价不设获奖等级，不区分个人或集体项目，参与即得分。
C5: 国家安全知识竞赛 | D5: 个人项目 | E5: 校级 | F5: 参与 | G5: =LOOKUP(0,0/((D5=得分表!C:C)*(E5=得分表!D:D)*(F5=得分表!E:E)),得分表!F:F) -> 6
C6: 管理学院2025年体育文化节暨院庆体育嘉年华趣味运动会集体跳绳 | D6: 集体项目 | E6: 校级 | F6: 参与 | G6: =LOOKUP(0,0/((D6=得分表!C:C)*(E6=得分表!D:D)*(F6=得分表!E:E)),得分表!F:F) -> 6
B7: 成果性 评价 | G7: =LOOKUP(0,0/((D7=得分表!J:J)*(E7=得分表!K:K)*(F7=得分表!L:L)),得分表!M:M) -> 0 | H7: =IF(SUM(G7:G16)<6,SUM(G7:G16),6) -> 0 | J7: 在体育竞赛中取得名次或奖项，为校院争得荣誉可在成果性评价计算加分，不累计加分，按单次最高得分计算。具体加分查看《管理学院本科生素质能力评价实施细则》“身心素养”部分。
G8: =LOOKUP(0,0/((D8=得分表!J:J)*(E8=得分表!K:K)*(F8=得分表!L:L)),得分表!M:M) -> 0
G9: =LOOKUP(0,0/((D9=得分表!J:J)*(E9=得分表!K:K)*(F9=得分表!L:L)),得分表!M:M) -> 0
G10: =LOOKUP(0,0/((D10=得分表!J:J)*(E10=得分表!K:K)*(F10=得分表!L:L)),得分表!M:M) -> 0
G11: =LOOKUP(0,0/((D11=得分表!J:J)*(E11=得分表!K:K)*(F11=得分表!L:L)),得分表!M:M) -> 0
G12: =LOOKUP(0,0/((D12=得分表!J:J)*(E12=得分表!K:K)*(F12=得分表!L:L)),得分表!M:M) -> 0
G13: =LOOKUP(0,0/((D13=得分表!J:J)*(E13=得分表!K:K)*(F13=得分表!L:L)),得分表!M:M) -> 0
G14: =LOOKUP(0,0/((D14=得分表!J:J)*(E14=得分表!K:K)*(F14=得分表!L:L)),得分表!M:M) -> 0
G15: =LOOKUP(0,0/((D15=得分表!J:J)*(E15=得分表!K:K)*(F15=得分表!L:L)),得分表!M:M) -> 0
G16: =LOOKUP(0,0/((D16=得分表!J:J)*(E16=得分表!K:K)*(F16=得分表!L:L)),得分表!M:M) -> 0
A17: 文 艺 素 养 | B17: 基础性 评价 | C17: 管理学院迎新晚会 | D17: 集体项目 | E17: 院级 | F17: 参与 | G17: =LOOKUP(0,0/((D17=得分表!Q:Q)*(E17=得分表!R:R)*(F17=得分表!S:S)),得分表!T:T) -> 3 | H17: =IF(SUM(G17:G19)<9,SUM(G17:G19),9) -> 3 | I17: =H17+H20 -> 3 | J17: 基础性评价不设获奖等级，不区分个人或集体项目，参与即得分。
G18: =LOOKUP(0,0/((D18=得分表!Q:Q)*(E18=得分表!R:R)*(F18=得分表!S:S)),得分表!T:T) -> 0
G19: =LOOKUP(0,0/((D19=得分表!Q:Q)*(E19=得分表!R:R)*(F19=得分表!S:S)),得分表!T:T) -> 0
B20: 成果性 评价 | G20: =LOOKUP(0,0/((D20=得分表!X:X)*(E20=得分表!Y:Y)*(F20=得分表!Z:Z)),得分表!AA:AA) -> 0 | H20: =IF(SUM(G20:G29)<6,SUM(G20:G29),6) -> 0 | J20: 参加文艺展演，在文艺竞赛中取得名次或奖项，为校院争得荣誉可在成果性评价计算加分，不累计加分，按单次最高得分计算。具体加分查看《管理学院本科生素质能力评价实施细则》“文艺素养”部分。 *大英赛等文化知识类竞赛获奖可在此加分
G21: =LOOKUP(0,0/((D21=得分表!X:X)*(E21=得分表!Y:Y)*(F21=得分表!Z:Z)),得分表!AA:AA) -> 0
G22: =LOOKUP(0,0/((D22=得分表!X:X)*(E22=得分表!Y:Y)*(F22=得分表!Z:Z)),得分表!AA:AA) -> 0
G23: =LOOKUP(0,0/((D23=得分表!X:X)*(E23=得分表!Y:Y)*(F23=得分表!Z:Z)),得分表!AA:AA) -> 0
G24: =LOOKUP(0,0/((D24=得分表!X:X)*(E24=得分表!Y:Y)*(F24=得分表!Z:Z)),得分表!AA:AA) -> 0
G25: =LOOKUP(0,0/((D25=得分表!X:X)*(E25=得分表!Y:Y)*(F25=得分表!Z:Z)),得分表!AA:AA) -> 0
G26: =LOOKUP(0,0/((D26=得分表!X:X)*(E26=得分表!Y:Y)*(F26=得分表!Z:Z)),得分表!AA:AA) -> 0
G27: =LOOKUP(0,0/((D27=得分表!X:X)*(E27=得分表!Y:Y)*(F27=得分表!Z:Z)),得分表!AA:AA) -> 0
G28: {=LOOKUP(0,0/(F28=得分表!Z:Z),得分表!AA:AA)} -> 0
G29: {=LOOKUP(0,0/(F29=得分表!Z:Z),得分表!AA:AA)} -> 0
A30: 劳 动 素 养 | B30: 基础性 评价 | D30: 社会工作(A) | E30: / | F30: 无任职 | G30: =LOOKUP(0,0/((D30=得分表!AE:AE)*(E30=得分表!AF:AF)*(F30=得分表!AG:AG)),得分表!AH:AH) -> 0 | H30: =IF(SUM(G30:G34)<15,SUM(G30:G34),15) -> 13 | I30: =H30+H35 -> 15.5 | J30: 本模块包含社会工作、社会实践、志愿服务、生涯发展、宿舍劳动五项基础加分，请按个人情况填写。
C31: 社会实践班级考评 | D31: 社会实践(B) | E31: / | F31: 考评合格 | G31: =LOOKUP(0,0/((D31=得分表!AE:AE)*(E31=得分表!AF:AF)*(F31=得分表!AG:AG)),得分表!AH:AH) -> 6
C32: 本学年志愿服务时长 | D32: 志愿服务(C) | E32: / | F32: C志愿时长满2小时 | G32: =LOOKUP(0,0/((D32=得分表!AE:AE)*(E32=得分表!AF:AF)*(F32=得分表!AG:AG)),得分表!AH:AH) -> 1
C33: 生涯发展类比赛：xxx | D33: 生涯发展(D) | E33: / | F33: 未参与 | G33: =LOOKUP(0,0/((D33=得分表!AE:AE)*(E33=得分表!AF:AF)*(F33=得分表!AG:AG)),得分表!AH:AH) -> 0
C34: xx号楼xx宿舍 | D34: 宿舍劳动(E) | E34: / | F34: 全年无不合格 | G34: =LOOKUP(0,0/((D34=得分表!AE:AE)*(E34=得分表!AF:AF)*(F34=得分表!AG:AG)),得分表!AH:AH) -> 6
B35: 成果性 评价 | D35: 社会工作(A) | G35: =LOOKUP(0,0/((E35=得分表!AM:AM)*(F35=得分表!AN:AN)),得分表!AO:AO) -> 0 | H35: =IF(SUM(G35:G61)<10,SUM(G35:G61),10) -> 2.5 | J35: 如获得集体荣誉，该任期内学生干部可获得加分，加分分为主要/其它两个等级。例：校先进班集体，班长、团支书为主要负责人，其它班委为其他学生干部。
G36: =LOOKUP(0,0/((E36=得分表!AM:AM)*(F36=得分表!AN:AN)),得分表!AO:AO) -> 0
G37: =LOOKUP(0,0/((E37=得分表!AM:AM)*(F37=得分表!AN:AN)),得分表!AO:AO) -> 0
G38: =LOOKUP(0,0/((E38=得分表!AM:AM)*(F38=得分表!AN:AN)),得分表!AO:AO) -> 0
C39: 2024-2025学年暑期社会实践校级立项 | D39: 社会实践(B) | E39: 校级 | F39: 团队其他成员 | G39: =LOOKUP(0,0/((E39=得分表!AM:AM)*(F39=得分表!AN:AN)),得分表!AO:AO) -> 2.5 | J39: 社会实践考评结果计入本学年基础性评价，社会实践个人、团队奖项计入下一学年综合测评。
G40: =LOOKUP(0,0/((E40=得分表!AM:AM)*(F40=得分表!AN:AN)),得分表!AO:AO) -> 0
...

Sheet 得分表
A1: 模块 | B1: 类别 | C1: 类型 | D1: 级别 | E1: 等级 | F1: 得分 | H1: 模块 | I1: 类别 | J1: 类型 | K1: 级别 | L1: 等级 | M1: 得分 | O1: 模块 | P1: 类别 | Q1: 类型 | R1: 级别 | S1: 等级 | T1: 得分 | V1: 模块 | W1: 类别 | X1: 类型 | Y1: 级别 | Z1: 等级 | AA1: 得分 | AC1: 模块 | AD1: 类别 | AE1: 类型 | AF1: 级别 | AG1: 等级 | AH1: 得分 | AJ1: 模块 | AK1: 类别 | AL1: 类型 | AM1: 级别 | AN1: 等级 | AO1: 得分
A2: 身心素养 | B2: 基础性评价 | C2: 个人项目 | D2: 院级 | E2: 参与 | F2: 3 | H2: 身心素养 | I2: 成果性评价 | J2: 个人项目 | K2: 国家级 | L2: 一等 | M2: 6 | O2: 文艺素养 | P2: 基础性评价 | Q2: 个人项目 | R2: 院级 | S2: 参与 | T2: 3 | V2: 文艺素养 | W2: 成果性评价 | X2: 个人项目 | Y2: 国家级 | Z2: 一等 | AA2: 6 | AC2: 劳动素养 | AD2: 基础性评价 | AE2: 社会工作(A) | AF2: / | AG2: 任职满一年 | AH2: 4 | AJ2: 劳动素养 | AK2: 成果性评价 | AL2: 社会工作(A) | AM2: 考核 | AN2: 合格/优秀（一年） | AO2: 4
A3: 身心素养 | B3: 基础性评价 | C3: 个人项目 | D3: 校级 | E3: 参与 | F3: 6 | H3: 身心素养 | I3: 成果性评价 | J3: 个人项目 | K3: 国家级 | L3: 二等 | M3: 5.25 | O3: 文艺素养 | P3: 基础性评价 | Q3: 个人项目 | R3: 校级 | S3: 参与 | T3: 6 | V3: 文艺素养 | W3: 成果性评价 | X3: 个人项目 | Y3: 国家级 | Z3: 二等 | AA3: 5.25 | AC3: 劳动素养 | AD3: 基础性评价 | AE3: 社会工作(A) | AF3: / | AG3: 任职满半年 | AH3: 2 | AJ3: 劳动素养 | AK3: 成果性评价 | AL3: 社会工作(A) | AM3: 考核 | AN3: 合格/优秀（半年） | AO3: 2
A4: 身心素养 | B4: 基础性评价 | C4: 个人项目 | D4: 地市级 | E4: 参与 | F4: 6 | H4: 身心素养 | I4: 成果性评价 | J4: 个人项目 | K4: 国家级 | L4: 三等 | M4: 4.5 | O4: 文艺素养 | P4: 基础性评价 | Q4: 个人项目 | R4: 地市级 | S4: 参与 | T4: 6 | V4: 文艺素养 | W4: 成果性评价 | X4: 个人项目 | Y4: 国家级 | Z4: 三等 | AA4: 3.75 | AC4: 劳动素养 | AD4: 基础性评价 | AE4: 社会工作(A) | AF4: / | AG4: 无任职 | AH4: 0 | AJ4: 劳动素养 | AK4: 成果性评价 | AL4: 社会工作(A) | AM4: 院级 | AN4: 个人荣誉/集体荣誉主要负责人 | AO4: 4
A5: 身心素养 | B5: 基础性评价 | C5: 个人项目 | D5: 省部级 | E5: 参与 | F5: 9 | H5: 身心素养 | I5: 成果性评价 | J5: 个人项目 | K5: 国家级 | L5: 其他等次 | M5: 3.75 | O5: 文艺素养 | P5: 基础性评价 | Q5: 个人项目 | R5: 省部级 | S5: 参与 | T5: 9 | V5: 文艺素养 | W5: 成果性评价 | X5: 个人项目 | Y5: 国家级 | Z5: 其他等次 | AA5: 3 | AC5: 劳动素养 | AD5: 基础性评价 | AE5: 社会实践(B) | AF5: / | AG5: 考评合格 | AH5: 6 | AJ5: 劳动素养 | AK5: 成果性评价 | AL5: 社会工作(A) | AM5: 校级 | AN5: 个人荣誉/集体荣誉主要负责人 | AO5: 5.5
A6: 身心素养 | B6: 基础性评价 | C6: 个人项目 | D6: 国家级 | E6: 参与 | F6: 9 | H6: 身心素养 | I6: 成果性评价 | J6: 个人项目 | K6: 省部级 | L6: 一等 | M6: 4.5 | O6: 文艺素养 | P6: 基础性评价 | Q6: 个人项目 | R6: 国家级 | S6: 参与 | T6: 9 | V6: 文艺素养 | W6: 成果性评价 | X6: 个人项目 | Y6: 省部级 | Z6: 一等 | AA6: 4.5 | AC6: 劳动素养 | AD6: 基础性评价 | AE6: 社会实践(B) | AF6: / | AG6: 考评优秀 | AH6: 9 | AJ6: 劳动素养 | AK6: 成果性评价 | AL6: 社会工作(A) | AM6: 地市级 | AN6: 个人荣誉/集体荣誉主要负责人 | AO6: 7
A7: 身心素养 | B7: 基础性评价 | C7: 集体项目 | D7: 院级 | E7: 参与 | F7: 3 | H7: 身心素养 | I7: 成果性评价 | J7: 个人项目 | K7: 省部级 | L7: 二等 | M7: 3.75 | O7: 文艺素养 | P7: 基础性评价 | Q7: 集体项目 | R7: 院级 | S7: 参与 | T7: 3 | V7: 文艺素养 | W7: 成果性评价 | X7: 个人项目 | Y7: 省部级 | Z7: 二等 | AA7: 3.75 | AC7: 劳动素养 | AD7: 基础性评价 | AE7: 社会实践(B) | AF7: / | AG7: 未考评 | AH7: 0 | AJ7: 劳动素养 | AK7: 成果性评价 | AL7: 社会工作(A) | AM7: 省部级 | AN7: 个人荣誉/集体荣誉主要负责人 | AO7: 8.5
A8: 身心素养 | B8: 基础性评价 | C8: 集体项目 | D8: 校级 | E8: 参与 | F8: 6 | H8: 身心素养 | I8: 成果性评价 | J8: 个人项目 | K8: 省部级 | L8: 三等 | M8: 3 | O8: 文艺素养 | P8: 基础性评价 | Q8: 集体项目 | R8: 校级 | S8: 参与 | T8: 6 | V8: 文艺素养 | W8: 成果性评价 | X8: 个人项目 | Y8: 省部级 | Z8: 三等 | AA8: 2.25 | AC8: 劳动素养 | AD8: 基础性评价 | AE8: 志愿服务(C) | AF8: / | AG8: C志愿时长不满2小时 | AH8: 0 | AJ8: 劳动素养 | AK8: 成果性评价 | AL8: 社会工作(A) | AM8: 国家级 | AN8: 个人荣誉/集体荣誉主要负责人 | AO8: 10
A9: 身心素养 | B9: 基础性评价 | C9: 集体项目 | D9: 地市级 | E9: 参与 | F9: 6 | H9: 身心素养 | I9: 成果性评价 | J9: 个人项目 | K9: 省部级 | L9: 其他等次 | M9: 2.25 | O9: 文艺素养 | P9: 基础性评价 | Q9: 集体项目 | R9: 地市级 | S9: 参与 | T9: 6 | V9: 文艺素养 | W9: 成果性评价 | X9: 个人项目 | Y9: 省部级 | Z9: 其他等次 | AA9: 1.5 | AC9: 劳动素养 | AD9: 基础性评价 | AE9: 志愿服务(C) | AF9: / | AG9: C志愿时长满2小时 | AH9: 1 | AJ9: 劳动素养 | AK9: 成果性评价 | AL9: 社会工作(A) | AM9: 院级 | AN9: 集体荣誉（其他学生干部） | AO9: 2.5
A10: 身心素养 | B10: 基础性评价 | C10: 集体项目 | D10: 省部级 | E10: 参与 | F10: 9 | H10: 身心素养 | I10: 成果性评价 | J10: 个人项目 | K10: 校级 | L10: 一等 | M10: 2.25 | O10: 文艺素养 | P10: 基础性评价 | Q10: 集体项目 | R10: 省部级 | S10: 参与 | T10: 9 | V10: 文艺素养 | W10: 成果性评价 | X10: 个人项目 | Y10: 校级 | Z10: 一等 | AA10: 3 | AC10: 劳动素养 | AD10: 基础性评价 | AE10: 志愿服务(C) | AF10: / | AG10: C志愿时长满4小时 | AH10: 2 | AJ10: 劳动素养 | AK10: 成果性评价 | AL10: 社会工作(A) | AM10: 校级 | AN10: 集体荣誉（其他学生干部） | AO10: 4
A11: 身心素养 | B11: 基础性评价 | C11: 集体项目 | D11: 国家级 | E11: 参与 | F11: 9 | H11: 身心素养 | I11: 成果性评价 | J11: 个人项目 | K11: 校级 | L11: 二等 | M11: 1.5 | O11: 文艺素养 | P11: 基础性评价 | Q11: 集体项目 | R11: 国家级 | S11: 参与 | T11: 9 | V11: 文艺素养 | W11: 成果性评价 | X11: 个人项目 | Y11: 校级 | Z11: 二等 | AA11: 2.25 | AC11: 劳动素养 | AD11: 基础性评价 | AE11: 志愿服务(C) | AF11: / | AG11: C志愿时长满6小时 | AH11: 3 | AJ11: 劳动素养 | AK11: 成果性评价 | AL11: 社会工作(A) | AM11: 地市级 | AN11: 集体荣誉（其他学生干部） | AO11: 5.5
H12: 身心素养 | I12: 成果性评价 | J12: 个人项目 | K12: 校级 | L12: 三等 | M12: 0.75 | O12: 文艺素养 | P12: 基础性评价 | Q12: 作者 | R12: 院级 | S12: 发表 | T12: 3 | V12: 文艺素养 | W12: 成果性评价 | X12: 个人项目 | Y12: 校级 | Z12: 三等 | AA12: 1.5 | AC12: 劳动素养 | AD12: 基础性评价 | AE12: 志愿服务(C) | AF12: / | AG12: C志愿时长满8小时 | AH12: 4 | AJ12: 劳动素养 | AK12: 成果性评价 | AL12: 社会工作(A) | AM12: 省部级 | AN12: 集体荣誉（其他学生干部） | AO12: 7
H13: 身心素养 | I13: 成果性评价 | J13: 个人项目 | K13: 校级 | L13: 其他等次 | M13: 0.375 | O13: 文艺素养 | P13: 基础性评价 | Q13: 作者 | R13: 校级 | S13: 发表 | T13: 6 | V13: 文艺素养 | W13: 成果性评价 | X13: 个人项目 | Y13: 校级 | Z13: 其他等次 | AA13: 0.75 | AC13: 劳动素养 | AD13: 基础性评价 | AE13: 志愿服务(C) | AF13: / | AG13: C志愿时长满10小时 | AH13: 5 | AJ13: 劳动素养 | AK13: 成果性评价 | AL13: 社会工作(A) | AM13: 国家级 | AN13: 集体荣誉（其他学生干部） | AO13: 8.5
H14: 身心素养 | I14: 成果性评价 | J14: 个人项目 | K14: 院级 | L14: 一等 | M14: 0.75 | V14: 文艺素养 | W14: 成果性评价 | X14: 个人项目 | Y14: 院级 | Z14: 一等 | AA14: 1.5 | AC14: 劳动素养 | AD14: 基础性评价 | AE14: 志愿服务(C) | AF14: / | AG14: C志愿时长满12小时 | AH14: 6
H15: 身心素养 | I15: 成果性评价 | J15: 个人项目 | K15: 院级 | L15: 二等 | M15: 0.375 | V15: 文艺素养 | W15: 成果性评价 | X15: 个人项目 | Y15: 院级 | Z15: 二等 | AA15: 0.75 | AC15: 劳动素养 | AD15: 基础性评价 | AE15: 志愿服务(C) | AF15: / | AG15: C志愿时长满14小时 | AH15: 7
H16: 身心素养 | I16: 成果性评价 | J16: 个人项目 | K16: 院级 | L16: 三等 | M16: 0.2 | V16: 文艺素养 | W16: 成果性评价 | X16: 个人项目 | Y16: 院级 | Z16: 三等 | AA16: 0.375 | AC16: 劳动素养 | AD16: 基础性评价 | AE16: 志愿服务(C) | AF16: / | AG16: C志愿时长满16小时 | AH16: 8
H17: 身心素养 | I17: 成果性评价 | J17: 个人项目 | K17: 院级 | L17: 其他等次 | M17: 0.1 | V17: 文艺素养 | W17: 成果性评价 | X17: 个人项目 | Y17: 院级 | Z17: 其他等次 | AA17: 0.2 | AC17: 劳动素养 | AD17: 基础性评价 | AE17: 志愿服务(C) | AF17: / | AG17: C志愿时长满18小时 | AH17: 9
H18: 身心素养 | I18: 成果性评价 | J18: 集体项目 | K18: 国家级 | L18: 一等 | M18: 6 | V18: 文艺素养 | W18: 成果性评价 | X18: 集体项目 | Y18: 国家级 | Z18: 一等 | AA18: 3.75 | AC18: 劳动素养 | AD18: 基础性评价 | AE18: 志愿服务(C) | AF18: / | AG18: C志愿时长满20小时 | AH18: 10
H19: 身心素养 | I19: 成果性评价 | J19: 集体项目 | K19: 国家级 | L19: 二等 | M19: 5.25 | V19: 文艺素养 | W19: 成果性评价 | X19: 集体项目 | Y19: 国家级 | Z19: 二等 | AA19: 3 | AC19: 劳动素养 | AD19: 基础性评价 | AE19: 志愿服务(C) | AF19: / | AG19: C志愿时长满22小时 | AH19: 11 | AJ19: 劳动素养 | AK19: 成果性评价 | AL19: 社会实践(B)/志愿服务(C) | AM19: 院级 | AN19: 个人荣誉称号/团队负责人 | AO19: 4
H20: 身心素养 | I20: 成果性评价 | J20: 集体项目 | K20: 国家级 | L20: 三等 | M20: 4.5 | V20: 文艺素养 | W20: 成果性评价 | X20: 集体项目 | Y20: 国家级 | Z20: 三等 | AA20: 2.25 | AC20: 劳动素养 | AD20: 基础性评价 | AE20: 志愿服务(C) | AF20: / | AG20: C志愿时长满24小时 | AH20: 12 | AJ20: 劳动素养 | AK20: 成果性评价 | AL20: 社会实践(B)/志愿服务(C) | AM20: 院级 | AN20: 团队其他成员 | AO20: 2
H21: 身心素养 | I21: 成果性评价 | J21: 集体项目 | K21: 国家级 | L21: 其他等次 | M21: 3.75 | V21: 文艺素养 | W21: 成果性评价 | X21: 集体项目 | Y21: 国家级 | Z21: 其他等次 | AA21: 1.5 | AC21: 劳动素养 | AD21: 基础性评价 | AE21: 志愿服务(C) | AF21: / | AG21: C志愿时长满26小时 | AH21: 13 | AJ21: 劳动素养 | AK21: 成果性评价 | AL21: 社会实践(B)/志愿服务(C) | AM21: 校级 | AN21: 个人荣誉称号/团队负责人 | AO21: 5.5
H22: 身心素养 | I22: 成果性评价 | J22: 集体项目 | K22: 省部级 | L22: 一等 | M22: 5.25 | V22: 文艺素养 | W22: 成果性评价 | X22: 集体项目 | Y22: 省部级 | Z22: 一等 | AA22: 3 | AC22: 劳动素养 | AD22: 基础性评价 | AE22: 志愿服务(C) | AF22: / | AG22: C志愿时长满28小时 | AH22: 14 | AJ22: 劳动素养 | AK22: 成果性评价 | AL22: 社会实践(B)/志愿服务(C) | AM22: 校级 | AN22: 团队其他成员 | AO22: 2.5
H23: 身心素养 | I23: 成果性评价 | J23: 集体项目 | K23: 省部级 | L23: 二等 | M23: 4.5 | V23: 文艺素养 | W23: 成果性评价 | X23: 集体项目 | Y23: 省部级 | Z23: 二等 | AA23: 2.25 | AC23: 劳动素养 | AD23: 基础性评价 | AE23: 志愿服务(C) | AF23: / | AG23: C志愿时长满30小时 | AH23: 15 | AJ23: 劳动素养 | AK23: 成果性评价 | AL23: 社会实践(B)/志愿服务(C) | AM23: 地市级 | AN23: 个人荣誉称号/团队负责人 | AO23: 7
H24: 身心素养 | I24: 成果性评价 | J24: 集体项目 | K24: 省部级 | L24: 三等 | M24: 3.75 | V24: 文艺素养 | W24: 成果性评价 | X24: 集体项目 | Y24: 省部级 | Z24: 三等 | AA24: 1.5 | AC24: 劳动素养 | AD24: 基础性评价 | AE24: 生涯发展(D) | AF24: / | AG24: 未参与 | AH24: 0 | AJ24: 劳动素养 | AK24: 成果性评价 | AL24: 社会实践(B)/志愿服务(C) | AM24: 地市级 | AN24: 团队其他成员 | AO24: 3
H25: 身心素养 | I25: 成果性评价 | J25: 集体项目 | K25: 省部级 | L25: 其他等次 | M25: 3 | V25: 文艺素养 | W25: 成果性评价 | X25: 集体项目 | Y25: 省部级 | Z25: 其他等次 | AA25: 0.75 | AC25: 劳动素养 | AD25: 基础性评价 | AE25: 生涯发展(D) | AF25: / | AG25: 院级-参与 | AH25: 3 | AJ25: 劳动素养 | AK25: 成果性评价 | AL25: 社会实践(B)/志愿服务(C) | AM25: 省部级 | AN25: 个人荣誉称号/团队负责人 | AO25: 8.5
H26: 身心素养 | I26: 成果性评价 | J26: 集体项目 | K26: 校级 | L26: 一等 | M26: 3 | V26: 文艺素养 | W26: 成果性评价 | X26: 集体项目 | Y26: 校级 | Z26: 一等 | AA26: 2.25 | AC26: 劳动素养 | AD26: 基础性评价 | AE26: 生涯发展(D) | AF26: / | AG26: 校级-参与 | AH26: 6 | AJ26: 劳动素养 | AK26: 成果性评价 | AL26: 社会实践(B)/志愿服务(C) | AM26: 省部级 | AN26: 团队其他成员 | AO26: 4
H27: 身心素养 | I27: 成果性评价 | J27: 集体项目 | K27: 校级 | L27: 二等 | M27: 2.25 | V27: 文艺素养 | W27: 成果性评价 | X27: 集体项目 | Y27: 校级 | Z27: 二等 | AA27: 1.5 | AC27: 劳动素养 | AD27: 基础性评价 | AE27: 生涯发展(D) | AF27: / | AG27: 省级及以上-参与 | AH27: 6 | AJ27: 劳动素养 | AK27: 成果性评价 | AL27: 社会实践(B)/志愿服务(C) | AM27: 国家级 | AN27: 个人荣誉称号/团队负责人 | AO27: 10
H28: 身心素养 | I28: 成果性评价 | J28: 集体项目 | K28: 校级 | L28: 三等 | M28: 1.5 | V28: 文艺素养 | W28: 成果性评价 | X28: 集体项目 | Y28: 校级 | Z28: 三等 | AA28: 0.75 | AC28: 劳动素养 | AD28: 基础性评价 | AE28: 宿舍劳动(E) | AF28: / | AG28: 全年无不合格 | AH28: 6 | AJ28: 劳动素养 | AK28: 成果性评价 | AL28: 社会实践(B)/志愿服务(C) | AM28: 国家级 | AN28: 团队其他成员 | AO28: 5.5
H29: 身心素养 | I29: 成果性评价 | J29: 集体项目 | K29: 校级 | L29: 其他等次 | M29: 0.75 | V29: 文艺素养 | W29: 成果性评价 | X29: 集体项目 | Y29: 校级 | Z29: 其他等次 | AA29: 0.375 | AC29: 劳动素养 | AD29: 基础性评价 | AE29: 宿舍劳动(E) | AF29: / | AG29: 全年无不合格并获1次优秀 | AH29: 9 | AJ29: 劳动素养 | AK29: 成果性评价 | AL29: 社会实践(B)/志愿服务(C) | AM29: 院级 | AN29: 一等-队长 | AO29: 4
H30: 身心素养 | I30: 成果性评价 | J30: 集体项目 | K30: 院级 | L30: 一等 | M30: 1.5 | V30: 文艺素养 | W30: 成果性评价 | X30: 集体项目 | Y30: 院级 | Z30: 一等 | AA30: 0.75 | AC30: 劳动素养 | AD30: 基础性评价 | AE30: 宿舍劳动(E) | AF30: / | AG30: 全年无不合格并获2次优秀 | AH30: 12 | AJ30: 劳动素养 | AK30: 成果性评价 | AL30: 社会实践(B)/志愿服务(C) | AM30: 院级 | AN30: 一等-其他成员 | AO30: 2
... H32: 身心素养 | I32: 成果性评价 | J32: 集体项目 | K32: 院级 | L32: 三等 | M32: 0.375 | V32: 文艺素养 | W32: 成果性评价 | X32: 集体项目 | Y32: 院级 | Z32: 三等 | AA32: 0.2 | AC32: 劳动素养 | AD32: 基础性评价 | AE32: 宿舍劳动(E) | AF32: / | AG32: 有不合格宿舍 | AH32: 0 | AJ32: 劳动素养 | AK32: 成果性评价 | AL32: 社会实践(B)/志愿服务(C) | AM32: 院级 | AN32: 二等-其他成员 | AO32: 1.25
H33: 身心素养 | I33: 成果性评价 | J33: 集体项目 | K33: 院级 | L33: 其他等次 | M33: 0.2 | V33: 文艺素养 | W33: 成果性评价 | X33: 集体项目 | Y33: 院级 | Z33: 其他等次 | AA33: 0.1 | AJ33: 劳动素养 | AK33: 成果性评价 | AL33: 社会实践(B)/志愿服务(C) | AM33: 院级 | AN33: 三等-队长 | AO33: 1.5
H34: 身心素养 | I34: 成果性评价 | J34: 个人项目 | K34: 院级 | L34: 破纪录 | M34: 1.75 | V34: 文艺素养 | W34: 成果性评价 | X34: 个人项目 | Y34: 院级 | Z34: 特等 | AA34: 2.5 | AJ34: 劳动素养 | AK34: 成果性评价 | AL34: 社会实践(B)/志愿服务(C) | AM34: 院级 | AN34: 三等-其他成员 | AO34: 0.75
H35: 身心素养 | I35: 成果性评价 | J35: 个人项目 | K35: 校级 | L35: 破纪录 | M35: 3.25 | V35: 文艺素养 | W35: 成果性评价 | X35: 个人项目 | Y35: 校级 | Z35: 特等 | AA35: 4 | AJ35: 劳动素养 | AK35: 成果性评价 | AL35: 社会实践(B)/志愿服务(C) | AM35: 院级 | AN35: 其他等次-队长 | AO35: 1
H36: 身心素养 | I36: 成果性评价 | J36: 个人项目 | K36: 省部级 | L36: 破纪录 | M36: 5.5 | V36: 文艺素养 | W36: 成果性评价 | X36: 个人项目 | Y36: 省部级 | Z36: 特等 | AA36: 5.5 | AJ36: 劳动素养 | AK36: 成果性评价 | AL36: 社会实践(B)/志愿服务(C) | AM36: 院级 | AN36: 其他等次-其他成员 | AO36: 0
H37: 身心素养 | I37: 成果性评价 | J37: 个人项目 | K37: 国家级 | L37: 破纪录 | M37: 7 | V37: 文艺素养 | W37: 成果性评价 | X37: 个人项目 | Y37: 国家级 | Z37: 特等 | AA37: 7 | AJ37: 劳动素养 | AK37: 成果性评价 | AL37: 社会实践(B)/志愿服务(C) | AM37: 校级 | AN37: 一等-队长 | AO37: 5.5
H38: 身心素养 | I38: 成果性评价 | J38: 集体项目 | K38: 院级 | L38: 破纪录 | M38: 2.5 | V38: 文艺素养 | W38: 成果性评价 | X38: 集体项目 | Y38: 院级 | Z38: 特等 | AA38: 1.75 | AJ38: 劳动素养 | AK38: 成果性评价 | AL38: 社会实践(B)/志愿服务(C) | AM38: 校级 | AN38: 一等-其他成员 | AO38: 2.75
H39: 身心素养 | I39: 成果性评价 | J39: 集体项目 | K39: 校级 | L39: 破纪录 | M39: 4 | V39: 文艺素养 | W39: 成果性评价 | X39: 集体项目 | Y39: 校级 | Z39: 特等 | AA39: 3.25 | AJ39: 劳动素养 | AK39: 成果性评价 | AL39: 社会实践(B)/志愿服务(C) | AM39: 校级 | AN39: 二等-队长 | AO39: 4
H40: 身心素养 | I40: 成果性评价 | J40: 集体项目 | K40: 省部级 | L40: 破纪录 | M40: 6.25 | V40: 文艺素养 | W40: 成果性评价 | X40: 集体项目 | Y40: 省部级 | Z40: 特等 | AA40: 4 | AJ40: 劳动素养 | AK40: 成果性评价 | AL40: 社会实践(B)/志愿服务(C) | AM40: 校级 | AN40: 二等-其他成员 | AO40: 2
H41: 身心素养 | I41: 成果性评价 | J41: 集体项目 | K41: 国家级 | L41: 破纪录 | M41: 7 | V41: 文艺素养 | W41: 成果性评价 | X41: 集体项目 | Y41: 国家级 | Z41: 特等 | AA41: 4.75 | AJ41: 劳动素养 | AK41: 成果性评价 | AL41: 社会实践(B)/志愿服务(C) | AM41: 校级 | AN41: 三等-队长 | AO41: 2.5
...
